<?xml version="1.0"?>
<robot name="thymio">
  <link name="base_link">
    <inertial>
      <mass value="0.200" />
      <inertia
        ixx="0.00024282" ixy="0" ixz="0"
        iyy="0.00023542" iyz="0"
        izz="0.00041073" />
    </inertial>
    <collision>
      <geometry>
        <mesh filename="package://thymio_description/meshes/thymio_body_collision.dae"/>
      </geometry>
    </collision>
    <collision>
      <origin xyz="0.035 0 0" />
      <geometry>
        <sphere radius="0.009"/>
      </geometry>
    </collision>
    <visual>
      <geometry>
        <mesh filename="package://thymio_description/meshes/thymio_body.dae"/>
      </geometry>
    </visual>
    <visual>
      <geometry>
        <mesh filename="package://thymio_description/meshes/thymio_proximity_sensors.dae"/>
      </geometry>
    </visual>
  </link>
  <joint name="left_wheel_joint" type="continuous">
    <parent link="base_link" />
    <child link="left_wheel_link" />
    <axis xyz="0 1 0" />
    <origin xyz="-0.025 0.047 0.013"/>
  </joint>
  <link name="left_wheel_link">
    <inertial>
      <mass value="0.025"/>
      <inertia
        ixx="0.00000363" ixy="0" ixz="0"
        iyy="0.00000605" iyz="0"
        izz="0.00000363" />
    </inertial>
    <collision>
      <origin xyz="0 0.00175 0" rpy="1.5707 0 0"/>
      <geometry>
        <cylinder radius="0.022" length="0.015"/>
      </geometry>
    </collision>
    <visual>
      <geometry>
        <mesh filename="package://thymio_description/meshes/thymio_left_wheel.dae"/>
      </geometry>
    </visual>
  </link>
  <joint name="right_wheel_joint" type="continuous">
    <parent link="base_link" />
    <child link="right_wheel_link" />
    <axis xyz="0 1 0" />
    <origin xyz="-0.025 -0.047 0.013"/>
  </joint>
  <link name="right_wheel_link">
    <inertial>
      <mass value="0.025"/>
      <inertia
        ixx="0.00000363" ixy="0" ixz="0"
        iyy="0.00000605" iyz="0"
        izz="0.00000363" />
    </inertial>
    <collision>
      <origin xyz="0 -0.00175 0" rpy="1.5707 0 0"/>
      <geometry>
        <cylinder radius="0.022" length="0.015"/>
      </geometry>
    </collision>
    <visual>
      <geometry>
        <mesh filename="package://thymio_description/meshes/thymio_right_wheel.dae"/>
      </geometry>
    </visual>
  </link>
  <link name="proximity_center_link"/>
  <link name="proximity_center_left_link"/>
  <link name="proximity_center_right_link"/>
  <link name="proximity_right_link"/>
  <link name="proximity_left_link"/>
  <link name="proximity_rear_right_link"/>
  <link name="proximity_rear_left_link"/>
  <link name="ground_right_link"/>
  <link name="ground_left_link"/>
  <joint name="proximity_center_joint" type="fixed">
    <origin xyz="0.055 0 0.026" rpy="0 0 0"/>
    <parent link="base_link"/>
    <child link="proximity_center_link"/>
  </joint>
  <joint name="proximity_center_left_joint" type="fixed">
    <origin xyz="0.0509 0.0252 0.026" rpy="0 0 0.32"/>
    <parent link="base_link"/>
    <child link="proximity_center_left_link"/>
  </joint>
  <joint name="proximity_left_joint" type="fixed">
    <origin xyz="0.0392 0.0478 0.026" rpy="0 0 0.64"/>
    <parent link="base_link"/>
    <child link="proximity_left_link"/>
  </joint>
  <joint name="proximity_center_right_joint" type="fixed">
    <origin xyz="0.0509 -0.0252 0.026" rpy="0 0 -0.32"/>
    <parent link="base_link"/>
    <child link="proximity_center_right_link"/>
  </joint>
  <joint name="proximity_right_joint" type="fixed">
    <origin xyz="0.0392 -0.0478 0.026" rpy="0 0 -0.64"/>
    <parent link="base_link"/>
    <child link="proximity_right_link"/>
  </joint>
  <joint name="proximity_rear_left_joint" type="fixed">
    <origin xyz="-0.055 0.03 0.026" rpy="0 0 3.1416"/>
    <parent link="base_link"/>
    <child link="proximity_rear_left_link"/>
  </joint>
  <joint name="proximity_rear_right_joint" type="fixed">
    <origin xyz="-0.055 -0.03 0.026" rpy="0 0 3.1416"/>
    <parent link="base_link"/>
    <child link="proximity_rear_right_link"/>
  </joint>
  <joint name="ground_right_joint" type="fixed">
    <origin xyz="0.04657 -0.01155 0.0" rpy="0 1.5708 0"/>
    <parent link="base_link"/>
    <child link="ground_right_link"/>
  </joint>
  <joint name="ground_left_joint" type="fixed">
    <origin xyz="0.04657 0.01155 0.0" rpy="0 1.5708 0"/>
    <parent link="base_link"/>
    <child link="ground_left_link"/>
  </joint>
</robot>
